[2020-01-27 17:11:26 +0000] [27250] [INFO] Starting gunicorn 20.0.4
[2020-01-27 17:12:23 +0000] [27284] [INFO] Starting gunicorn 20.0.4
[2020-01-27 17:12:46 +0000] [27289] [INFO] Starting gunicorn 20.0.4
[2020-01-27 17:12:53 +0000] [27295] [INFO] Starting gunicorn 20.0.4
[2020-01-27 17:12:53 +0000] [27295] [INFO] Listening at: http://127.0.0.1:12345 (27295)
[2020-01-27 17:12:53 +0000] [27295] [INFO] Using worker: sync
[2020-01-27 17:12:53 +0000] [27298] [INFO] Booting worker with pid: 27298
[2020-01-27 20:12:54 +0300] [27298] [ERROR] Exception in worker process
Traceback (most recent call last):
  File "/home/artem/.local/lib/python3.5/site-packages/gunicorn/arbiter.py", line 583, in spawn_worker
    worker.init_process()
  File "/home/artem/.local/lib/python3.5/site-packages/gunicorn/workers/base.py", line 119, in init_process
    self.load_wsgi()
  File "/home/artem/.local/lib/python3.5/site-packages/gunicorn/workers/base.py", line 144, in load_wsgi
    self.wsgi = self.app.wsgi()
  File "/home/artem/.local/lib/python3.5/site-packages/gunicorn/app/base.py", line 67, in wsgi
    self.callable = self.load()
  File "/home/artem/.local/lib/python3.5/site-packages/gunicorn/app/wsgiapp.py", line 49, in load
    return self.load_wsgiapp()
  File "/home/artem/.local/lib/python3.5/site-packages/gunicorn/app/wsgiapp.py", line 39, in load_wsgiapp
    return util.import_app(self.app_uri)
  File "/home/artem/.local/lib/python3.5/site-packages/gunicorn/util.py", line 358, in import_app
    mod = importlib.import_module(module)
  File "/usr/lib/python3.5/importlib/__init__.py", line 126, in import_module
    return _bootstrap._gcd_import(name[level:], package, level)
  File "<frozen importlib._bootstrap>", line 986, in _gcd_import
  File "<frozen importlib._bootstrap>", line 969, in _find_and_load
  File "<frozen importlib._bootstrap>", line 958, in _find_and_load_unlocked
  File "<frozen importlib._bootstrap>", line 673, in _load_unlocked
  File "<frozen importlib._bootstrap_external>", line 665, in exec_module
  File "<frozen importlib._bootstrap>", line 222, in _call_with_frames_removed
  File "/home/artem/poeapi/poeapi/wsgi.py", line 16, in <module>
    application = get_wsgi_application()
  File "/home/artem/.local/lib/python3.5/site-packages/django/core/wsgi.py", line 12, in get_wsgi_application
    django.setup(set_prefix=False)
  File "/home/artem/.local/lib/python3.5/site-packages/django/__init__.py", line 24, in setup
    apps.populate(settings.INSTALLED_APPS)
  File "/home/artem/.local/lib/python3.5/site-packages/django/apps/registry.py", line 91, in populate
    app_config = AppConfig.create(entry)
  File "/home/artem/.local/lib/python3.5/site-packages/django/apps/config.py", line 90, in create
    module = import_module(entry)
  File "/usr/lib/python3.5/importlib/__init__.py", line 126, in import_module
    return _bootstrap._gcd_import(name[level:], package, level)
  File "<frozen importlib._bootstrap>", line 986, in _gcd_import
  File "<frozen importlib._bootstrap>", line 969, in _find_and_load
  File "<frozen importlib._bootstrap>", line 958, in _find_and_load_unlocked
  File "<frozen importlib._bootstrap>", line 673, in _load_unlocked
  File "<frozen importlib._bootstrap_external>", line 665, in exec_module
  File "<frozen importlib._bootstrap>", line 222, in _call_with_frames_removed
  File "/home/artem/poeapi/api/__init__.py", line 1, in <module>
    from api.dataputter import DataPutter
  File "/home/artem/poeapi/api/dataputter.py", line 42
    print(f'Collected {len(items)} items.')
                                         ^
SyntaxError: invalid syntax
[2020-01-27 20:12:54 +0300] [27298] [INFO] Worker exiting (pid: 27298)
[2020-01-27 17:12:54 +0000] [27295] [INFO] Shutting down: Master
[2020-01-27 17:12:54 +0000] [27295] [INFO] Reason: Worker failed to boot.
[2020-01-27 17:15:26 +0000] [27449] [INFO] Starting gunicorn 19.4.5
[2020-01-27 17:15:27 +0000] [27457] [INFO] Starting gunicorn 19.4.5
[2020-01-27 17:15:30 +0000] [27460] [INFO] Starting gunicorn 19.4.5
[2020-01-27 17:15:33 +0000] [27464] [INFO] Starting gunicorn 19.4.5
[2020-01-27 17:25:11 +0000] [27894] [INFO] Starting gunicorn 19.4.5
[2020-01-27 17:25:12 +0000] [27902] [INFO] Starting gunicorn 19.4.5
[2020-01-27 17:25:15 +0000] [27907] [INFO] Starting gunicorn 19.4.5
[2020-01-27 17:25:18 +0000] [27910] [INFO] Starting gunicorn 19.4.5
[2020-01-27 17:25:41 +0000] [27924] [INFO] Starting gunicorn 19.4.5
[2020-01-27 17:26:19 +0000] [27959] [INFO] Starting gunicorn 19.4.5
[2020-01-27 17:26:27 +0000] [27964] [INFO] Starting gunicorn 19.4.5
[2020-01-27 17:26:27 +0000] [27964] [INFO] Listening at: http://127.0.0.1:12345 (27964)
[2020-01-27 17:26:27 +0000] [27964] [INFO] Using worker: sync
[2020-01-27 17:26:27 +0000] [27967] [INFO] Booting worker with pid: 27967
[2020-01-27 17:26:27 +0000] [27967] [ERROR] Exception in worker process:
Traceback (most recent call last):
  File "/usr/lib/python3/dist-packages/gunicorn/arbiter.py", line 515, in spawn_worker
    worker.init_process()
  File "/usr/lib/python3/dist-packages/gunicorn/workers/base.py", line 122, in init_process
    self.load_wsgi()
  File "/usr/lib/python3/dist-packages/gunicorn/workers/base.py", line 130, in load_wsgi
    self.wsgi = self.app.wsgi()
  File "/usr/lib/python3/dist-packages/gunicorn/app/base.py", line 67, in wsgi
    self.callable = self.load()
  File "/usr/lib/python3/dist-packages/gunicorn/app/wsgiapp.py", line 65, in load
    return self.load_wsgiapp()
  File "/usr/lib/python3/dist-packages/gunicorn/app/wsgiapp.py", line 52, in load_wsgiapp
    return util.import_app(self.app_uri)
  File "/usr/lib/python3/dist-packages/gunicorn/util.py", line 366, in import_app
    __import__(module)
ImportError: No module named 'poeapi'
Traceback (most recent call last):
  File "/usr/lib/python3/dist-packages/gunicorn/arbiter.py", line 515, in spawn_worker
    worker.init_process()
  File "/usr/lib/python3/dist-packages/gunicorn/workers/base.py", line 122, in init_process
    self.load_wsgi()
  File "/usr/lib/python3/dist-packages/gunicorn/workers/base.py", line 130, in load_wsgi
    self.wsgi = self.app.wsgi()
  File "/usr/lib/python3/dist-packages/gunicorn/app/base.py", line 67, in wsgi
    self.callable = self.load()
  File "/usr/lib/python3/dist-packages/gunicorn/app/wsgiapp.py", line 65, in load
    return self.load_wsgiapp()
  File "/usr/lib/python3/dist-packages/gunicorn/app/wsgiapp.py", line 52, in load_wsgiapp
    return util.import_app(self.app_uri)
  File "/usr/lib/python3/dist-packages/gunicorn/util.py", line 366, in import_app
    __import__(module)
ImportError: No module named 'poeapi'
[2020-01-27 17:26:27 +0000] [27967] [INFO] Worker exiting (pid: 27967)
[2020-01-27 17:26:27 +0000] [27964] [INFO] Shutting down: Master
[2020-01-27 17:26:27 +0000] [27964] [INFO] Reason: Worker failed to boot.
[2020-01-27 17:27:44 +0000] [28023] [INFO] Starting gunicorn 19.4.5
[2020-01-27 17:27:44 +0000] [28023] [INFO] Listening at: http://127.0.0.1:12345 (28023)
[2020-01-27 17:27:44 +0000] [28023] [INFO] Using worker: sync
[2020-01-27 17:27:44 +0000] [28027] [INFO] Booting worker with pid: 28027
[2020-01-27 17:27:44 +0000] [28027] [ERROR] Exception in worker process:
Traceback (most recent call last):
  File "/usr/lib/python3/dist-packages/gunicorn/arbiter.py", line 515, in spawn_worker
    worker.init_process()
  File "/usr/lib/python3/dist-packages/gunicorn/workers/base.py", line 122, in init_process
    self.load_wsgi()
  File "/usr/lib/python3/dist-packages/gunicorn/workers/base.py", line 130, in load_wsgi
    self.wsgi = self.app.wsgi()
  File "/usr/lib/python3/dist-packages/gunicorn/app/base.py", line 67, in wsgi
    self.callable = self.load()
  File "/usr/lib/python3/dist-packages/gunicorn/app/wsgiapp.py", line 65, in load
    return self.load_wsgiapp()
  File "/usr/lib/python3/dist-packages/gunicorn/app/wsgiapp.py", line 52, in load_wsgiapp
    return util.import_app(self.app_uri)
  File "/usr/lib/python3/dist-packages/gunicorn/util.py", line 366, in import_app
    __import__(module)
ImportError: No module named 'poeapi'
Traceback (most recent call last):
  File "/usr/lib/python3/dist-packages/gunicorn/arbiter.py", line 515, in spawn_worker
    worker.init_process()
  File "/usr/lib/python3/dist-packages/gunicorn/workers/base.py", line 122, in init_process
    self.load_wsgi()
  File "/usr/lib/python3/dist-packages/gunicorn/workers/base.py", line 130, in load_wsgi
    self.wsgi = self.app.wsgi()
  File "/usr/lib/python3/dist-packages/gunicorn/app/base.py", line 67, in wsgi
    self.callable = self.load()
  File "/usr/lib/python3/dist-packages/gunicorn/app/wsgiapp.py", line 65, in load
    return self.load_wsgiapp()
  File "/usr/lib/python3/dist-packages/gunicorn/app/wsgiapp.py", line 52, in load_wsgiapp
    return util.import_app(self.app_uri)
  File "/usr/lib/python3/dist-packages/gunicorn/util.py", line 366, in import_app
    __import__(module)
ImportError: No module named 'poeapi'
[2020-01-27 17:27:44 +0000] [28027] [INFO] Worker exiting (pid: 28027)
[2020-01-27 17:27:44 +0000] [28023] [INFO] Shutting down: Master
[2020-01-27 17:27:44 +0000] [28023] [INFO] Reason: Worker failed to boot.
[2020-01-27 17:28:04 +0000] [28048] [INFO] Starting gunicorn 19.4.5
[2020-01-27 17:28:04 +0000] [28048] [INFO] Listening at: http://127.0.0.1:12345 (28048)
[2020-01-27 17:28:04 +0000] [28048] [INFO] Using worker: sync
[2020-01-27 17:28:04 +0000] [28051] [INFO] Booting worker with pid: 28051
[2020-01-27 20:28:05 +0300] [28051] [ERROR] Exception in worker process:
Traceback (most recent call last):
  File "/usr/lib/python3/dist-packages/gunicorn/arbiter.py", line 515, in spawn_worker
    worker.init_process()
  File "/usr/lib/python3/dist-packages/gunicorn/workers/base.py", line 122, in init_process
    self.load_wsgi()
  File "/usr/lib/python3/dist-packages/gunicorn/workers/base.py", line 130, in load_wsgi
    self.wsgi = self.app.wsgi()
  File "/usr/lib/python3/dist-packages/gunicorn/app/base.py", line 67, in wsgi
    self.callable = self.load()
  File "/usr/lib/python3/dist-packages/gunicorn/app/wsgiapp.py", line 65, in load
    return self.load_wsgiapp()
  File "/usr/lib/python3/dist-packages/gunicorn/app/wsgiapp.py", line 52, in load_wsgiapp
    return util.import_app(self.app_uri)
  File "/usr/lib/python3/dist-packages/gunicorn/util.py", line 366, in import_app
    __import__(module)
  File "/home/artem/poeapi/poeapi/wsgi.py", line 16, in <module>
    application = get_wsgi_application()
  File "/home/artem/.local/lib/python3.5/site-packages/django/core/wsgi.py", line 12, in get_wsgi_application
    django.setup(set_prefix=False)
  File "/home/artem/.local/lib/python3.5/site-packages/django/__init__.py", line 24, in setup
    apps.populate(settings.INSTALLED_APPS)
  File "/home/artem/.local/lib/python3.5/site-packages/django/apps/registry.py", line 91, in populate
    app_config = AppConfig.create(entry)
  File "/home/artem/.local/lib/python3.5/site-packages/django/apps/config.py", line 90, in create
    module = import_module(entry)
  File "/usr/lib/python3.5/importlib/__init__.py", line 126, in import_module
    return _bootstrap._gcd_import(name[level:], package, level)
  File "/home/artem/poeapi/api/__init__.py", line 1, in <module>
    from api.dataputter import DataPutter
  File "/home/artem/poeapi/api/dataputter.py", line 42
    print(f'Collected {len(items)} items.')
                                         ^
SyntaxError: invalid syntax
Traceback (most recent call last):
  File "/usr/lib/python3/dist-packages/gunicorn/arbiter.py", line 515, in spawn_worker
    worker.init_process()
  File "/usr/lib/python3/dist-packages/gunicorn/workers/base.py", line 122, in init_process
    self.load_wsgi()
  File "/usr/lib/python3/dist-packages/gunicorn/workers/base.py", line 130, in load_wsgi
    self.wsgi = self.app.wsgi()
  File "/usr/lib/python3/dist-packages/gunicorn/app/base.py", line 67, in wsgi
    self.callable = self.load()
  File "/usr/lib/python3/dist-packages/gunicorn/app/wsgiapp.py", line 65, in load
    return self.load_wsgiapp()
  File "/usr/lib/python3/dist-packages/gunicorn/app/wsgiapp.py", line 52, in load_wsgiapp
    return util.import_app(self.app_uri)
  File "/usr/lib/python3/dist-packages/gunicorn/util.py", line 366, in import_app
    __import__(module)
  File "/home/artem/poeapi/poeapi/wsgi.py", line 16, in <module>
    application = get_wsgi_application()
  File "/home/artem/.local/lib/python3.5/site-packages/django/core/wsgi.py", line 12, in get_wsgi_application
    django.setup(set_prefix=False)
  File "/home/artem/.local/lib/python3.5/site-packages/django/__init__.py", line 24, in setup
    apps.populate(settings.INSTALLED_APPS)
  File "/home/artem/.local/lib/python3.5/site-packages/django/apps/registry.py", line 91, in populate
    app_config = AppConfig.create(entry)
  File "/home/artem/.local/lib/python3.5/site-packages/django/apps/config.py", line 90, in create
    module = import_module(entry)
  File "/usr/lib/python3.5/importlib/__init__.py", line 126, in import_module
    return _bootstrap._gcd_import(name[level:], package, level)
  File "/home/artem/poeapi/api/__init__.py", line 1, in <module>
    from api.dataputter import DataPutter
  File "/home/artem/poeapi/api/dataputter.py", line 42
    print(f'Collected {len(items)} items.')
                                         ^
SyntaxError: invalid syntax
[2020-01-27 20:28:05 +0300] [28051] [INFO] Worker exiting (pid: 28051)
[2020-01-27 17:28:05 +0000] [28048] [INFO] Shutting down: Master
[2020-01-27 17:28:05 +0000] [28048] [INFO] Reason: Worker failed to boot.
[2020-01-27 17:28:06 +0000] [28053] [INFO] Starting gunicorn 19.4.5
[2020-01-27 17:28:06 +0000] [28053] [INFO] Listening at: http://127.0.0.1:12345 (28053)
[2020-01-27 17:28:06 +0000] [28053] [INFO] Using worker: sync
[2020-01-27 17:28:06 +0000] [28056] [INFO] Booting worker with pid: 28056
[2020-01-27 20:28:07 +0300] [28056] [ERROR] Exception in worker process:
Traceback (most recent call last):
  File "/usr/lib/python3/dist-packages/gunicorn/arbiter.py", line 515, in spawn_worker
    worker.init_process()
  File "/usr/lib/python3/dist-packages/gunicorn/workers/base.py", line 122, in init_process
    self.load_wsgi()
  File "/usr/lib/python3/dist-packages/gunicorn/workers/base.py", line 130, in load_wsgi
    self.wsgi = self.app.wsgi()
  File "/usr/lib/python3/dist-packages/gunicorn/app/base.py", line 67, in wsgi
    self.callable = self.load()
  File "/usr/lib/python3/dist-packages/gunicorn/app/wsgiapp.py", line 65, in load
    return self.load_wsgiapp()
  File "/usr/lib/python3/dist-packages/gunicorn/app/wsgiapp.py", line 52, in load_wsgiapp
    return util.import_app(self.app_uri)
  File "/usr/lib/python3/dist-packages/gunicorn/util.py", line 366, in import_app
    __import__(module)
  File "/home/artem/poeapi/poeapi/wsgi.py", line 16, in <module>
    application = get_wsgi_application()
  File "/home/artem/.local/lib/python3.5/site-packages/django/core/wsgi.py", line 12, in get_wsgi_application
    django.setup(set_prefix=False)
  File "/home/artem/.local/lib/python3.5/site-packages/django/__init__.py", line 24, in setup
    apps.populate(settings.INSTALLED_APPS)
  File "/home/artem/.local/lib/python3.5/site-packages/django/apps/registry.py", line 91, in populate
    app_config = AppConfig.create(entry)
  File "/home/artem/.local/lib/python3.5/site-packages/django/apps/config.py", line 90, in create
    module = import_module(entry)
  File "/usr/lib/python3.5/importlib/__init__.py", line 126, in import_module
    return _bootstrap._gcd_import(name[level:], package, level)
  File "/home/artem/poeapi/api/__init__.py", line 1, in <module>
    from api.dataputter import DataPutter
  File "/home/artem/poeapi/api/dataputter.py", line 42
    print(f'Collected {len(items)} items.')
                                         ^
SyntaxError: invalid syntax
Traceback (most recent call last):
  File "/usr/lib/python3/dist-packages/gunicorn/arbiter.py", line 515, in spawn_worker
    worker.init_process()
  File "/usr/lib/python3/dist-packages/gunicorn/workers/base.py", line 122, in init_process
    self.load_wsgi()
  File "/usr/lib/python3/dist-packages/gunicorn/workers/base.py", line 130, in load_wsgi
    self.wsgi = self.app.wsgi()
  File "/usr/lib/python3/dist-packages/gunicorn/app/base.py", line 67, in wsgi
    self.callable = self.load()
  File "/usr/lib/python3/dist-packages/gunicorn/app/wsgiapp.py", line 65, in load
    return self.load_wsgiapp()
  File "/usr/lib/python3/dist-packages/gunicorn/app/wsgiapp.py", line 52, in load_wsgiapp
    return util.import_app(self.app_uri)
  File "/usr/lib/python3/dist-packages/gunicorn/util.py", line 366, in import_app
    __import__(module)
  File "/home/artem/poeapi/poeapi/wsgi.py", line 16, in <module>
    application = get_wsgi_application()
  File "/home/artem/.local/lib/python3.5/site-packages/django/core/wsgi.py", line 12, in get_wsgi_application
    django.setup(set_prefix=False)
  File "/home/artem/.local/lib/python3.5/site-packages/django/__init__.py", line 24, in setup
    apps.populate(settings.INSTALLED_APPS)
  File "/home/artem/.local/lib/python3.5/site-packages/django/apps/registry.py", line 91, in populate
    app_config = AppConfig.create(entry)
  File "/home/artem/.local/lib/python3.5/site-packages/django/apps/config.py", line 90, in create
    module = import_module(entry)
  File "/usr/lib/python3.5/importlib/__init__.py", line 126, in import_module
    return _bootstrap._gcd_import(name[level:], package, level)
  File "/home/artem/poeapi/api/__init__.py", line 1, in <module>
    from api.dataputter import DataPutter
  File "/home/artem/poeapi/api/dataputter.py", line 42
    print(f'Collected {len(items)} items.')
                                         ^
SyntaxError: invalid syntax
[2020-01-27 20:28:07 +0300] [28056] [INFO] Worker exiting (pid: 28056)
[2020-01-27 17:28:07 +0000] [28053] [INFO] Shutting down: Master
[2020-01-27 17:28:07 +0000] [28053] [INFO] Reason: Worker failed to boot.
[2020-01-27 17:28:10 +0000] [28062] [INFO] Starting gunicorn 19.4.5
[2020-01-27 17:28:10 +0000] [28062] [INFO] Listening at: http://127.0.0.1:12345 (28062)
[2020-01-27 17:28:10 +0000] [28062] [INFO] Using worker: sync
[2020-01-27 17:28:10 +0000] [28065] [INFO] Booting worker with pid: 28065
[2020-01-27 20:28:10 +0300] [28065] [ERROR] Exception in worker process:
Traceback (most recent call last):
  File "/usr/lib/python3/dist-packages/gunicorn/arbiter.py", line 515, in spawn_worker
    worker.init_process()
  File "/usr/lib/python3/dist-packages/gunicorn/workers/base.py", line 122, in init_process
    self.load_wsgi()
  File "/usr/lib/python3/dist-packages/gunicorn/workers/base.py", line 130, in load_wsgi
    self.wsgi = self.app.wsgi()
  File "/usr/lib/python3/dist-packages/gunicorn/app/base.py", line 67, in wsgi
    self.callable = self.load()
  File "/usr/lib/python3/dist-packages/gunicorn/app/wsgiapp.py", line 65, in load
    return self.load_wsgiapp()
  File "/usr/lib/python3/dist-packages/gunicorn/app/wsgiapp.py", line 52, in load_wsgiapp
    return util.import_app(self.app_uri)
  File "/usr/lib/python3/dist-packages/gunicorn/util.py", line 366, in import_app
    __import__(module)
  File "/home/artem/poeapi/poeapi/wsgi.py", line 16, in <module>
    application = get_wsgi_application()
  File "/home/artem/.local/lib/python3.5/site-packages/django/core/wsgi.py", line 12, in get_wsgi_application
    django.setup(set_prefix=False)
  File "/home/artem/.local/lib/python3.5/site-packages/django/__init__.py", line 24, in setup
    apps.populate(settings.INSTALLED_APPS)
  File "/home/artem/.local/lib/python3.5/site-packages/django/apps/registry.py", line 91, in populate
    app_config = AppConfig.create(entry)
  File "/home/artem/.local/lib/python3.5/site-packages/django/apps/config.py", line 90, in create
    module = import_module(entry)
  File "/usr/lib/python3.5/importlib/__init__.py", line 126, in import_module
    return _bootstrap._gcd_import(name[level:], package, level)
  File "/home/artem/poeapi/api/__init__.py", line 1, in <module>
    from api.dataputter import DataPutter
  File "/home/artem/poeapi/api/dataputter.py", line 42
    print(f'Collected {len(items)} items.')
                                         ^
SyntaxError: invalid syntax
Traceback (most recent call last):
  File "/usr/lib/python3/dist-packages/gunicorn/arbiter.py", line 515, in spawn_worker
    worker.init_process()
  File "/usr/lib/python3/dist-packages/gunicorn/workers/base.py", line 122, in init_process
    self.load_wsgi()
  File "/usr/lib/python3/dist-packages/gunicorn/workers/base.py", line 130, in load_wsgi
    self.wsgi = self.app.wsgi()
  File "/usr/lib/python3/dist-packages/gunicorn/app/base.py", line 67, in wsgi
    self.callable = self.load()
  File "/usr/lib/python3/dist-packages/gunicorn/app/wsgiapp.py", line 65, in load
    return self.load_wsgiapp()
  File "/usr/lib/python3/dist-packages/gunicorn/app/wsgiapp.py", line 52, in load_wsgiapp
    return util.import_app(self.app_uri)
  File "/usr/lib/python3/dist-packages/gunicorn/util.py", line 366, in import_app
    __import__(module)
  File "/home/artem/poeapi/poeapi/wsgi.py", line 16, in <module>
    application = get_wsgi_application()
  File "/home/artem/.local/lib/python3.5/site-packages/django/core/wsgi.py", line 12, in get_wsgi_application
    django.setup(set_prefix=False)
  File "/home/artem/.local/lib/python3.5/site-packages/django/__init__.py", line 24, in setup
    apps.populate(settings.INSTALLED_APPS)
  File "/home/artem/.local/lib/python3.5/site-packages/django/apps/registry.py", line 91, in populate
    app_config = AppConfig.create(entry)
  File "/home/artem/.local/lib/python3.5/site-packages/django/apps/config.py", line 90, in create
    module = import_module(entry)
  File "/usr/lib/python3.5/importlib/__init__.py", line 126, in import_module
    return _bootstrap._gcd_import(name[level:], package, level)
  File "/home/artem/poeapi/api/__init__.py", line 1, in <module>
    from api.dataputter import DataPutter
  File "/home/artem/poeapi/api/dataputter.py", line 42
    print(f'Collected {len(items)} items.')
                                         ^
SyntaxError: invalid syntax
[2020-01-27 20:28:10 +0300] [28065] [INFO] Worker exiting (pid: 28065)
[2020-01-27 17:28:10 +0000] [28062] [INFO] Shutting down: Master
[2020-01-27 17:28:10 +0000] [28062] [INFO] Reason: Worker failed to boot.
[2020-01-27 17:28:14 +0000] [28067] [INFO] Starting gunicorn 19.4.5
[2020-01-27 17:28:14 +0000] [28067] [INFO] Listening at: http://127.0.0.1:12345 (28067)
[2020-01-27 17:28:14 +0000] [28067] [INFO] Using worker: sync
[2020-01-27 17:28:14 +0000] [28070] [INFO] Booting worker with pid: 28070
[2020-01-27 20:28:14 +0300] [28070] [ERROR] Exception in worker process:
Traceback (most recent call last):
  File "/usr/lib/python3/dist-packages/gunicorn/arbiter.py", line 515, in spawn_worker
    worker.init_process()
  File "/usr/lib/python3/dist-packages/gunicorn/workers/base.py", line 122, in init_process
    self.load_wsgi()
  File "/usr/lib/python3/dist-packages/gunicorn/workers/base.py", line 130, in load_wsgi
    self.wsgi = self.app.wsgi()
  File "/usr/lib/python3/dist-packages/gunicorn/app/base.py", line 67, in wsgi
    self.callable = self.load()
  File "/usr/lib/python3/dist-packages/gunicorn/app/wsgiapp.py", line 65, in load
    return self.load_wsgiapp()
  File "/usr/lib/python3/dist-packages/gunicorn/app/wsgiapp.py", line 52, in load_wsgiapp
    return util.import_app(self.app_uri)
  File "/usr/lib/python3/dist-packages/gunicorn/util.py", line 366, in import_app
    __import__(module)
  File "/home/artem/poeapi/poeapi/wsgi.py", line 16, in <module>
    application = get_wsgi_application()
  File "/home/artem/.local/lib/python3.5/site-packages/django/core/wsgi.py", line 12, in get_wsgi_application
    django.setup(set_prefix=False)
  File "/home/artem/.local/lib/python3.5/site-packages/django/__init__.py", line 24, in setup
    apps.populate(settings.INSTALLED_APPS)
  File "/home/artem/.local/lib/python3.5/site-packages/django/apps/registry.py", line 91, in populate
    app_config = AppConfig.create(entry)
  File "/home/artem/.local/lib/python3.5/site-packages/django/apps/config.py", line 90, in create
    module = import_module(entry)
  File "/usr/lib/python3.5/importlib/__init__.py", line 126, in import_module
    return _bootstrap._gcd_import(name[level:], package, level)
  File "/home/artem/poeapi/api/__init__.py", line 1, in <module>
    from api.dataputter import DataPutter
  File "/home/artem/poeapi/api/dataputter.py", line 42
    print(f'Collected {len(items)} items.')
                                         ^
SyntaxError: invalid syntax
Traceback (most recent call last):
  File "/usr/lib/python3/dist-packages/gunicorn/arbiter.py", line 515, in spawn_worker
    worker.init_process()
  File "/usr/lib/python3/dist-packages/gunicorn/workers/base.py", line 122, in init_process
    self.load_wsgi()
  File "/usr/lib/python3/dist-packages/gunicorn/workers/base.py", line 130, in load_wsgi
    self.wsgi = self.app.wsgi()
  File "/usr/lib/python3/dist-packages/gunicorn/app/base.py", line 67, in wsgi
    self.callable = self.load()
  File "/usr/lib/python3/dist-packages/gunicorn/app/wsgiapp.py", line 65, in load
    return self.load_wsgiapp()
  File "/usr/lib/python3/dist-packages/gunicorn/app/wsgiapp.py", line 52, in load_wsgiapp
    return util.import_app(self.app_uri)
  File "/usr/lib/python3/dist-packages/gunicorn/util.py", line 366, in import_app
    __import__(module)
  File "/home/artem/poeapi/poeapi/wsgi.py", line 16, in <module>
    application = get_wsgi_application()
  File "/home/artem/.local/lib/python3.5/site-packages/django/core/wsgi.py", line 12, in get_wsgi_application
    django.setup(set_prefix=False)
  File "/home/artem/.local/lib/python3.5/site-packages/django/__init__.py", line 24, in setup
    apps.populate(settings.INSTALLED_APPS)
  File "/home/artem/.local/lib/python3.5/site-packages/django/apps/registry.py", line 91, in populate
    app_config = AppConfig.create(entry)
  File "/home/artem/.local/lib/python3.5/site-packages/django/apps/config.py", line 90, in create
    module = import_module(entry)
  File "/usr/lib/python3.5/importlib/__init__.py", line 126, in import_module
    return _bootstrap._gcd_import(name[level:], package, level)
  File "/home/artem/poeapi/api/__init__.py", line 1, in <module>
    from api.dataputter import DataPutter
  File "/home/artem/poeapi/api/dataputter.py", line 42
    print(f'Collected {len(items)} items.')
                                         ^
SyntaxError: invalid syntax
[2020-01-27 20:28:14 +0300] [28070] [INFO] Worker exiting (pid: 28070)
[2020-01-27 17:28:14 +0000] [28067] [INFO] Shutting down: Master
[2020-01-27 17:28:14 +0000] [28067] [INFO] Reason: Worker failed to boot.
[2020-01-27 17:38:38 +0000] [28553] [INFO] Starting gunicorn 19.4.5
[2020-01-27 17:38:38 +0000] [28553] [INFO] Listening at: http://127.0.0.1:12345 (28553)
[2020-01-27 17:38:38 +0000] [28553] [INFO] Using worker: sync
[2020-01-27 17:38:38 +0000] [28556] [INFO] Booting worker with pid: 28556
[2020-01-27 20:38:39 +0300] [28556] [ERROR] Exception in worker process:
Traceback (most recent call last):
  File "/usr/lib/python3/dist-packages/gunicorn/arbiter.py", line 515, in spawn_worker
    worker.init_process()
  File "/usr/lib/python3/dist-packages/gunicorn/workers/base.py", line 122, in init_process
    self.load_wsgi()
  File "/usr/lib/python3/dist-packages/gunicorn/workers/base.py", line 130, in load_wsgi
    self.wsgi = self.app.wsgi()
  File "/usr/lib/python3/dist-packages/gunicorn/app/base.py", line 67, in wsgi
    self.callable = self.load()
  File "/usr/lib/python3/dist-packages/gunicorn/app/wsgiapp.py", line 65, in load
    return self.load_wsgiapp()
  File "/usr/lib/python3/dist-packages/gunicorn/app/wsgiapp.py", line 52, in load_wsgiapp
    return util.import_app(self.app_uri)
  File "/usr/lib/python3/dist-packages/gunicorn/util.py", line 366, in import_app
    __import__(module)
  File "/home/artem/poeapi/poeapi/wsgi.py", line 16, in <module>
    application = get_wsgi_application()
  File "/home/artem/.local/lib/python3.5/site-packages/django/core/wsgi.py", line 12, in get_wsgi_application
    django.setup(set_prefix=False)
  File "/home/artem/.local/lib/python3.5/site-packages/django/__init__.py", line 24, in setup
    apps.populate(settings.INSTALLED_APPS)
  File "/home/artem/.local/lib/python3.5/site-packages/django/apps/registry.py", line 91, in populate
    app_config = AppConfig.create(entry)
  File "/home/artem/.local/lib/python3.5/site-packages/django/apps/config.py", line 90, in create
    module = import_module(entry)
  File "/usr/lib/python3.5/importlib/__init__.py", line 126, in import_module
    return _bootstrap._gcd_import(name[level:], package, level)
  File "/home/artem/poeapi/api/__init__.py", line 1, in <module>
    from api.dataputter import DataPutter
  File "/home/artem/poeapi/api/dataputter.py", line 42
    print(f'Collected {len(items)} items.')
                                         ^
SyntaxError: invalid syntax
Traceback (most recent call last):
  File "/usr/lib/python3/dist-packages/gunicorn/arbiter.py", line 515, in spawn_worker
    worker.init_process()
  File "/usr/lib/python3/dist-packages/gunicorn/workers/base.py", line 122, in init_process
    self.load_wsgi()
  File "/usr/lib/python3/dist-packages/gunicorn/workers/base.py", line 130, in load_wsgi
    self.wsgi = self.app.wsgi()
  File "/usr/lib/python3/dist-packages/gunicorn/app/base.py", line 67, in wsgi
    self.callable = self.load()
  File "/usr/lib/python3/dist-packages/gunicorn/app/wsgiapp.py", line 65, in load
    return self.load_wsgiapp()
  File "/usr/lib/python3/dist-packages/gunicorn/app/wsgiapp.py", line 52, in load_wsgiapp
    return util.import_app(self.app_uri)
  File "/usr/lib/python3/dist-packages/gunicorn/util.py", line 366, in import_app
    __import__(module)
  File "/home/artem/poeapi/poeapi/wsgi.py", line 16, in <module>
    application = get_wsgi_application()
  File "/home/artem/.local/lib/python3.5/site-packages/django/core/wsgi.py", line 12, in get_wsgi_application
    django.setup(set_prefix=False)
  File "/home/artem/.local/lib/python3.5/site-packages/django/__init__.py", line 24, in setup
    apps.populate(settings.INSTALLED_APPS)
  File "/home/artem/.local/lib/python3.5/site-packages/django/apps/registry.py", line 91, in populate
    app_config = AppConfig.create(entry)
  File "/home/artem/.local/lib/python3.5/site-packages/django/apps/config.py", line 90, in create
    module = import_module(entry)
  File "/usr/lib/python3.5/importlib/__init__.py", line 126, in import_module
    return _bootstrap._gcd_import(name[level:], package, level)
  File "/home/artem/poeapi/api/__init__.py", line 1, in <module>
    from api.dataputter import DataPutter
  File "/home/artem/poeapi/api/dataputter.py", line 42
    print(f'Collected {len(items)} items.')
                                         ^
SyntaxError: invalid syntax
[2020-01-27 20:38:39 +0300] [28556] [INFO] Worker exiting (pid: 28556)
[2020-01-27 17:38:39 +0000] [28553] [INFO] Shutting down: Master
[2020-01-27 17:38:39 +0000] [28553] [INFO] Reason: Worker failed to boot.
[2020-01-27 17:38:40 +0000] [28558] [INFO] Starting gunicorn 19.4.5
[2020-01-27 17:38:40 +0000] [28558] [INFO] Listening at: http://127.0.0.1:12345 (28558)
[2020-01-27 17:38:40 +0000] [28558] [INFO] Using worker: sync
[2020-01-27 17:38:40 +0000] [28561] [INFO] Booting worker with pid: 28561
[2020-01-27 20:38:41 +0300] [28561] [ERROR] Exception in worker process:
Traceback (most recent call last):
  File "/usr/lib/python3/dist-packages/gunicorn/arbiter.py", line 515, in spawn_worker
    worker.init_process()
  File "/usr/lib/python3/dist-packages/gunicorn/workers/base.py", line 122, in init_process
    self.load_wsgi()
  File "/usr/lib/python3/dist-packages/gunicorn/workers/base.py", line 130, in load_wsgi
    self.wsgi = self.app.wsgi()
  File "/usr/lib/python3/dist-packages/gunicorn/app/base.py", line 67, in wsgi
    self.callable = self.load()
  File "/usr/lib/python3/dist-packages/gunicorn/app/wsgiapp.py", line 65, in load
    return self.load_wsgiapp()
  File "/usr/lib/python3/dist-packages/gunicorn/app/wsgiapp.py", line 52, in load_wsgiapp
    return util.import_app(self.app_uri)
  File "/usr/lib/python3/dist-packages/gunicorn/util.py", line 366, in import_app
    __import__(module)
  File "/home/artem/poeapi/poeapi/wsgi.py", line 16, in <module>
    application = get_wsgi_application()
  File "/home/artem/.local/lib/python3.5/site-packages/django/core/wsgi.py", line 12, in get_wsgi_application
    django.setup(set_prefix=False)
  File "/home/artem/.local/lib/python3.5/site-packages/django/__init__.py", line 24, in setup
    apps.populate(settings.INSTALLED_APPS)
  File "/home/artem/.local/lib/python3.5/site-packages/django/apps/registry.py", line 91, in populate
    app_config = AppConfig.create(entry)
  File "/home/artem/.local/lib/python3.5/site-packages/django/apps/config.py", line 90, in create
    module = import_module(entry)
  File "/usr/lib/python3.5/importlib/__init__.py", line 126, in import_module
    return _bootstrap._gcd_import(name[level:], package, level)
  File "/home/artem/poeapi/api/__init__.py", line 1, in <module>
    from api.dataputter import DataPutter
  File "/home/artem/poeapi/api/dataputter.py", line 42
    print(f'Collected {len(items)} items.')
                                         ^
SyntaxError: invalid syntax
Traceback (most recent call last):
  File "/usr/lib/python3/dist-packages/gunicorn/arbiter.py", line 515, in spawn_worker
    worker.init_process()
  File "/usr/lib/python3/dist-packages/gunicorn/workers/base.py", line 122, in init_process
    self.load_wsgi()
  File "/usr/lib/python3/dist-packages/gunicorn/workers/base.py", line 130, in load_wsgi
    self.wsgi = self.app.wsgi()
  File "/usr/lib/python3/dist-packages/gunicorn/app/base.py", line 67, in wsgi
    self.callable = self.load()
  File "/usr/lib/python3/dist-packages/gunicorn/app/wsgiapp.py", line 65, in load
    return self.load_wsgiapp()
  File "/usr/lib/python3/dist-packages/gunicorn/app/wsgiapp.py", line 52, in load_wsgiapp
    return util.import_app(self.app_uri)
  File "/usr/lib/python3/dist-packages/gunicorn/util.py", line 366, in import_app
    __import__(module)
  File "/home/artem/poeapi/poeapi/wsgi.py", line 16, in <module>
    application = get_wsgi_application()
  File "/home/artem/.local/lib/python3.5/site-packages/django/core/wsgi.py", line 12, in get_wsgi_application
    django.setup(set_prefix=False)
  File "/home/artem/.local/lib/python3.5/site-packages/django/__init__.py", line 24, in setup
    apps.populate(settings.INSTALLED_APPS)
  File "/home/artem/.local/lib/python3.5/site-packages/django/apps/registry.py", line 91, in populate
    app_config = AppConfig.create(entry)
  File "/home/artem/.local/lib/python3.5/site-packages/django/apps/config.py", line 90, in create
    module = import_module(entry)
  File "/usr/lib/python3.5/importlib/__init__.py", line 126, in import_module
    return _bootstrap._gcd_import(name[level:], package, level)
  File "/home/artem/poeapi/api/__init__.py", line 1, in <module>
    from api.dataputter import DataPutter
  File "/home/artem/poeapi/api/dataputter.py", line 42
    print(f'Collected {len(items)} items.')
                                         ^
SyntaxError: invalid syntax
[2020-01-27 20:38:41 +0300] [28561] [INFO] Worker exiting (pid: 28561)
[2020-01-27 17:38:41 +0000] [28558] [INFO] Shutting down: Master
[2020-01-27 17:38:41 +0000] [28558] [INFO] Reason: Worker failed to boot.
[2020-01-27 17:38:43 +0000] [28563] [INFO] Starting gunicorn 19.4.5
[2020-01-27 17:38:43 +0000] [28563] [INFO] Listening at: http://127.0.0.1:12345 (28563)
[2020-01-27 17:38:43 +0000] [28563] [INFO] Using worker: sync
[2020-01-27 17:38:43 +0000] [28566] [INFO] Booting worker with pid: 28566
[2020-01-27 20:38:43 +0300] [28566] [ERROR] Exception in worker process:
Traceback (most recent call last):
  File "/usr/lib/python3/dist-packages/gunicorn/arbiter.py", line 515, in spawn_worker
    worker.init_process()
  File "/usr/lib/python3/dist-packages/gunicorn/workers/base.py", line 122, in init_process
    self.load_wsgi()
  File "/usr/lib/python3/dist-packages/gunicorn/workers/base.py", line 130, in load_wsgi
    self.wsgi = self.app.wsgi()
  File "/usr/lib/python3/dist-packages/gunicorn/app/base.py", line 67, in wsgi
    self.callable = self.load()
  File "/usr/lib/python3/dist-packages/gunicorn/app/wsgiapp.py", line 65, in load
    return self.load_wsgiapp()
  File "/usr/lib/python3/dist-packages/gunicorn/app/wsgiapp.py", line 52, in load_wsgiapp
    return util.import_app(self.app_uri)
  File "/usr/lib/python3/dist-packages/gunicorn/util.py", line 366, in import_app
    __import__(module)
  File "/home/artem/poeapi/poeapi/wsgi.py", line 16, in <module>
    application = get_wsgi_application()
  File "/home/artem/.local/lib/python3.5/site-packages/django/core/wsgi.py", line 12, in get_wsgi_application
    django.setup(set_prefix=False)
  File "/home/artem/.local/lib/python3.5/site-packages/django/__init__.py", line 24, in setup
    apps.populate(settings.INSTALLED_APPS)
  File "/home/artem/.local/lib/python3.5/site-packages/django/apps/registry.py", line 91, in populate
    app_config = AppConfig.create(entry)
  File "/home/artem/.local/lib/python3.5/site-packages/django/apps/config.py", line 90, in create
    module = import_module(entry)
  File "/usr/lib/python3.5/importlib/__init__.py", line 126, in import_module
    return _bootstrap._gcd_import(name[level:], package, level)
  File "/home/artem/poeapi/api/__init__.py", line 1, in <module>
    from api.dataputter import DataPutter
  File "/home/artem/poeapi/api/dataputter.py", line 42
    print(f'Collected {len(items)} items.')
                                         ^
SyntaxError: invalid syntax
Traceback (most recent call last):
  File "/usr/lib/python3/dist-packages/gunicorn/arbiter.py", line 515, in spawn_worker
    worker.init_process()
  File "/usr/lib/python3/dist-packages/gunicorn/workers/base.py", line 122, in init_process
    self.load_wsgi()
  File "/usr/lib/python3/dist-packages/gunicorn/workers/base.py", line 130, in load_wsgi
    self.wsgi = self.app.wsgi()
  File "/usr/lib/python3/dist-packages/gunicorn/app/base.py", line 67, in wsgi
    self.callable = self.load()
  File "/usr/lib/python3/dist-packages/gunicorn/app/wsgiapp.py", line 65, in load
    return self.load_wsgiapp()
  File "/usr/lib/python3/dist-packages/gunicorn/app/wsgiapp.py", line 52, in load_wsgiapp
    return util.import_app(self.app_uri)
  File "/usr/lib/python3/dist-packages/gunicorn/util.py", line 366, in import_app
    __import__(module)
  File "/home/artem/poeapi/poeapi/wsgi.py", line 16, in <module>
    application = get_wsgi_application()
  File "/home/artem/.local/lib/python3.5/site-packages/django/core/wsgi.py", line 12, in get_wsgi_application
    django.setup(set_prefix=False)
  File "/home/artem/.local/lib/python3.5/site-packages/django/__init__.py", line 24, in setup
    apps.populate(settings.INSTALLED_APPS)
  File "/home/artem/.local/lib/python3.5/site-packages/django/apps/registry.py", line 91, in populate
    app_config = AppConfig.create(entry)
  File "/home/artem/.local/lib/python3.5/site-packages/django/apps/config.py", line 90, in create
    module = import_module(entry)
  File "/usr/lib/python3.5/importlib/__init__.py", line 126, in import_module
    return _bootstrap._gcd_import(name[level:], package, level)
  File "/home/artem/poeapi/api/__init__.py", line 1, in <module>
    from api.dataputter import DataPutter
  File "/home/artem/poeapi/api/dataputter.py", line 42
    print(f'Collected {len(items)} items.')
                                         ^
SyntaxError: invalid syntax
[2020-01-27 20:38:43 +0300] [28566] [INFO] Worker exiting (pid: 28566)
[2020-01-27 17:38:43 +0000] [28563] [INFO] Shutting down: Master
[2020-01-27 17:38:43 +0000] [28563] [INFO] Reason: Worker failed to boot.
[2020-01-27 17:38:47 +0000] [28568] [INFO] Starting gunicorn 19.4.5
[2020-01-27 17:38:47 +0000] [28568] [INFO] Listening at: http://127.0.0.1:12345 (28568)
[2020-01-27 17:38:47 +0000] [28568] [INFO] Using worker: sync
[2020-01-27 17:38:47 +0000] [28571] [INFO] Booting worker with pid: 28571
[2020-01-27 20:38:47 +0300] [28571] [ERROR] Exception in worker process:
Traceback (most recent call last):
  File "/usr/lib/python3/dist-packages/gunicorn/arbiter.py", line 515, in spawn_worker
    worker.init_process()
  File "/usr/lib/python3/dist-packages/gunicorn/workers/base.py", line 122, in init_process
    self.load_wsgi()
  File "/usr/lib/python3/dist-packages/gunicorn/workers/base.py", line 130, in load_wsgi
    self.wsgi = self.app.wsgi()
  File "/usr/lib/python3/dist-packages/gunicorn/app/base.py", line 67, in wsgi
    self.callable = self.load()
  File "/usr/lib/python3/dist-packages/gunicorn/app/wsgiapp.py", line 65, in load
    return self.load_wsgiapp()
  File "/usr/lib/python3/dist-packages/gunicorn/app/wsgiapp.py", line 52, in load_wsgiapp
    return util.import_app(self.app_uri)
  File "/usr/lib/python3/dist-packages/gunicorn/util.py", line 366, in import_app
    __import__(module)
  File "/home/artem/poeapi/poeapi/wsgi.py", line 16, in <module>
    application = get_wsgi_application()
  File "/home/artem/.local/lib/python3.5/site-packages/django/core/wsgi.py", line 12, in get_wsgi_application
    django.setup(set_prefix=False)
  File "/home/artem/.local/lib/python3.5/site-packages/django/__init__.py", line 24, in setup
    apps.populate(settings.INSTALLED_APPS)
  File "/home/artem/.local/lib/python3.5/site-packages/django/apps/registry.py", line 91, in populate
    app_config = AppConfig.create(entry)
  File "/home/artem/.local/lib/python3.5/site-packages/django/apps/config.py", line 90, in create
    module = import_module(entry)
  File "/usr/lib/python3.5/importlib/__init__.py", line 126, in import_module
    return _bootstrap._gcd_import(name[level:], package, level)
  File "/home/artem/poeapi/api/__init__.py", line 1, in <module>
    from api.dataputter import DataPutter
  File "/home/artem/poeapi/api/dataputter.py", line 42
    print(f'Collected {len(items)} items.')
                                         ^
SyntaxError: invalid syntax
Traceback (most recent call last):
  File "/usr/lib/python3/dist-packages/gunicorn/arbiter.py", line 515, in spawn_worker
    worker.init_process()
  File "/usr/lib/python3/dist-packages/gunicorn/workers/base.py", line 122, in init_process
    self.load_wsgi()
  File "/usr/lib/python3/dist-packages/gunicorn/workers/base.py", line 130, in load_wsgi
    self.wsgi = self.app.wsgi()
  File "/usr/lib/python3/dist-packages/gunicorn/app/base.py", line 67, in wsgi
    self.callable = self.load()
  File "/usr/lib/python3/dist-packages/gunicorn/app/wsgiapp.py", line 65, in load
    return self.load_wsgiapp()
  File "/usr/lib/python3/dist-packages/gunicorn/app/wsgiapp.py", line 52, in load_wsgiapp
    return util.import_app(self.app_uri)
  File "/usr/lib/python3/dist-packages/gunicorn/util.py", line 366, in import_app
    __import__(module)
  File "/home/artem/poeapi/poeapi/wsgi.py", line 16, in <module>
    application = get_wsgi_application()
  File "/home/artem/.local/lib/python3.5/site-packages/django/core/wsgi.py", line 12, in get_wsgi_application
    django.setup(set_prefix=False)
  File "/home/artem/.local/lib/python3.5/site-packages/django/__init__.py", line 24, in setup
    apps.populate(settings.INSTALLED_APPS)
  File "/home/artem/.local/lib/python3.5/site-packages/django/apps/registry.py", line 91, in populate
    app_config = AppConfig.create(entry)
  File "/home/artem/.local/lib/python3.5/site-packages/django/apps/config.py", line 90, in create
    module = import_module(entry)
  File "/usr/lib/python3.5/importlib/__init__.py", line 126, in import_module
    return _bootstrap._gcd_import(name[level:], package, level)
  File "/home/artem/poeapi/api/__init__.py", line 1, in <module>
    from api.dataputter import DataPutter
  File "/home/artem/poeapi/api/dataputter.py", line 42
    print(f'Collected {len(items)} items.')
                                         ^
SyntaxError: invalid syntax
[2020-01-27 20:38:47 +0300] [28571] [INFO] Worker exiting (pid: 28571)
[2020-01-27 17:38:47 +0000] [28568] [INFO] Shutting down: Master
[2020-01-27 17:38:47 +0000] [28568] [INFO] Reason: Worker failed to boot.
[2020-01-27 17:44:17 +0000] [28953] [INFO] Starting gunicorn 19.4.5
[2020-01-27 17:44:17 +0000] [28953] [INFO] Listening at: http://127.0.0.1:12345 (28953)
[2020-01-27 17:44:17 +0000] [28953] [INFO] Using worker: sync
[2020-01-27 17:44:17 +0000] [28956] [INFO] Booting worker with pid: 28956
[2020-01-27 17:44:17 +0000] [28956] [ERROR] Exception in worker process:
Traceback (most recent call last):
  File "/usr/lib/python3/dist-packages/gunicorn/arbiter.py", line 515, in spawn_worker
    worker.init_process()
  File "/usr/lib/python3/dist-packages/gunicorn/workers/base.py", line 122, in init_process
    self.load_wsgi()
  File "/usr/lib/python3/dist-packages/gunicorn/workers/base.py", line 130, in load_wsgi
    self.wsgi = self.app.wsgi()
  File "/usr/lib/python3/dist-packages/gunicorn/app/base.py", line 67, in wsgi
    self.callable = self.load()
  File "/usr/lib/python3/dist-packages/gunicorn/app/wsgiapp.py", line 65, in load
    return self.load_wsgiapp()
  File "/usr/lib/python3/dist-packages/gunicorn/app/wsgiapp.py", line 52, in load_wsgiapp
    return util.import_app(self.app_uri)
  File "/usr/lib/python3/dist-packages/gunicorn/util.py", line 366, in import_app
    __import__(module)
  File "/home/artem/poeapi/poeapi/__init__.py", line 4, in <module>
    from .celery import app as celery_app
  File "/home/artem/poeapi/poeapi/celery.py", line 3, in <module>
    from celery import Celery
ImportError: No module named 'celery'
Traceback (most recent call last):
  File "/usr/lib/python3/dist-packages/gunicorn/arbiter.py", line 515, in spawn_worker
    worker.init_process()
  File "/usr/lib/python3/dist-packages/gunicorn/workers/base.py", line 122, in init_process
    self.load_wsgi()
  File "/usr/lib/python3/dist-packages/gunicorn/workers/base.py", line 130, in load_wsgi
    self.wsgi = self.app.wsgi()
  File "/usr/lib/python3/dist-packages/gunicorn/app/base.py", line 67, in wsgi
    self.callable = self.load()
  File "/usr/lib/python3/dist-packages/gunicorn/app/wsgiapp.py", line 65, in load
    return self.load_wsgiapp()
  File "/usr/lib/python3/dist-packages/gunicorn/app/wsgiapp.py", line 52, in load_wsgiapp
    return util.import_app(self.app_uri)
  File "/usr/lib/python3/dist-packages/gunicorn/util.py", line 366, in import_app
    __import__(module)
  File "/home/artem/poeapi/poeapi/__init__.py", line 4, in <module>
    from .celery import app as celery_app
  File "/home/artem/poeapi/poeapi/celery.py", line 3, in <module>
    from celery import Celery
ImportError: No module named 'celery'
[2020-01-27 17:44:17 +0000] [28956] [INFO] Worker exiting (pid: 28956)
[2020-01-27 17:44:17 +0000] [28953] [INFO] Shutting down: Master
[2020-01-27 17:44:17 +0000] [28953] [INFO] Reason: Worker failed to boot.
[2020-01-27 17:44:18 +0000] [28957] [INFO] Starting gunicorn 19.4.5
[2020-01-27 17:44:18 +0000] [28957] [INFO] Listening at: http://127.0.0.1:12345 (28957)
[2020-01-27 17:44:18 +0000] [28957] [INFO] Using worker: sync
[2020-01-27 17:44:18 +0000] [28960] [INFO] Booting worker with pid: 28960
[2020-01-27 17:44:18 +0000] [28960] [ERROR] Exception in worker process:
Traceback (most recent call last):
  File "/usr/lib/python3/dist-packages/gunicorn/arbiter.py", line 515, in spawn_worker
    worker.init_process()
  File "/usr/lib/python3/dist-packages/gunicorn/workers/base.py", line 122, in init_process
    self.load_wsgi()
  File "/usr/lib/python3/dist-packages/gunicorn/workers/base.py", line 130, in load_wsgi
    self.wsgi = self.app.wsgi()
  File "/usr/lib/python3/dist-packages/gunicorn/app/base.py", line 67, in wsgi
    self.callable = self.load()
  File "/usr/lib/python3/dist-packages/gunicorn/app/wsgiapp.py", line 65, in load
    return self.load_wsgiapp()
  File "/usr/lib/python3/dist-packages/gunicorn/app/wsgiapp.py", line 52, in load_wsgiapp
    return util.import_app(self.app_uri)
  File "/usr/lib/python3/dist-packages/gunicorn/util.py", line 366, in import_app
    __import__(module)
  File "/home/artem/poeapi/poeapi/__init__.py", line 4, in <module>
    from .celery import app as celery_app
  File "/home/artem/poeapi/poeapi/celery.py", line 3, in <module>
    from celery import Celery
ImportError: No module named 'celery'
Traceback (most recent call last):
  File "/usr/lib/python3/dist-packages/gunicorn/arbiter.py", line 515, in spawn_worker
    worker.init_process()
  File "/usr/lib/python3/dist-packages/gunicorn/workers/base.py", line 122, in init_process
    self.load_wsgi()
  File "/usr/lib/python3/dist-packages/gunicorn/workers/base.py", line 130, in load_wsgi
    self.wsgi = self.app.wsgi()
  File "/usr/lib/python3/dist-packages/gunicorn/app/base.py", line 67, in wsgi
    self.callable = self.load()
  File "/usr/lib/python3/dist-packages/gunicorn/app/wsgiapp.py", line 65, in load
    return self.load_wsgiapp()
  File "/usr/lib/python3/dist-packages/gunicorn/app/wsgiapp.py", line 52, in load_wsgiapp
    return util.import_app(self.app_uri)
  File "/usr/lib/python3/dist-packages/gunicorn/util.py", line 366, in import_app
    __import__(module)
  File "/home/artem/poeapi/poeapi/__init__.py", line 4, in <module>
    from .celery import app as celery_app
  File "/home/artem/poeapi/poeapi/celery.py", line 3, in <module>
    from celery import Celery
ImportError: No module named 'celery'
[2020-01-27 17:44:18 +0000] [28960] [INFO] Worker exiting (pid: 28960)
[2020-01-27 17:44:18 +0000] [28957] [INFO] Shutting down: Master
[2020-01-27 17:44:18 +0000] [28957] [INFO] Reason: Worker failed to boot.
[2020-01-27 17:44:20 +0000] [28961] [INFO] Starting gunicorn 19.4.5
[2020-01-27 17:44:20 +0000] [28961] [INFO] Listening at: http://127.0.0.1:12345 (28961)
[2020-01-27 17:44:20 +0000] [28961] [INFO] Using worker: sync
[2020-01-27 17:44:20 +0000] [28964] [INFO] Booting worker with pid: 28964
[2020-01-27 17:44:20 +0000] [28964] [ERROR] Exception in worker process:
Traceback (most recent call last):
  File "/usr/lib/python3/dist-packages/gunicorn/arbiter.py", line 515, in spawn_worker
    worker.init_process()
  File "/usr/lib/python3/dist-packages/gunicorn/workers/base.py", line 122, in init_process
    self.load_wsgi()
  File "/usr/lib/python3/dist-packages/gunicorn/workers/base.py", line 130, in load_wsgi
    self.wsgi = self.app.wsgi()
  File "/usr/lib/python3/dist-packages/gunicorn/app/base.py", line 67, in wsgi
    self.callable = self.load()
  File "/usr/lib/python3/dist-packages/gunicorn/app/wsgiapp.py", line 65, in load
    return self.load_wsgiapp()
  File "/usr/lib/python3/dist-packages/gunicorn/app/wsgiapp.py", line 52, in load_wsgiapp
    return util.import_app(self.app_uri)
  File "/usr/lib/python3/dist-packages/gunicorn/util.py", line 366, in import_app
    __import__(module)
  File "/home/artem/poeapi/poeapi/__init__.py", line 4, in <module>
    from .celery import app as celery_app
  File "/home/artem/poeapi/poeapi/celery.py", line 3, in <module>
    from celery import Celery
ImportError: No module named 'celery'
Traceback (most recent call last):
  File "/usr/lib/python3/dist-packages/gunicorn/arbiter.py", line 515, in spawn_worker
    worker.init_process()
  File "/usr/lib/python3/dist-packages/gunicorn/workers/base.py", line 122, in init_process
    self.load_wsgi()
  File "/usr/lib/python3/dist-packages/gunicorn/workers/base.py", line 130, in load_wsgi
    self.wsgi = self.app.wsgi()
  File "/usr/lib/python3/dist-packages/gunicorn/app/base.py", line 67, in wsgi
    self.callable = self.load()
  File "/usr/lib/python3/dist-packages/gunicorn/app/wsgiapp.py", line 65, in load
    return self.load_wsgiapp()
  File "/usr/lib/python3/dist-packages/gunicorn/app/wsgiapp.py", line 52, in load_wsgiapp
    return util.import_app(self.app_uri)
  File "/usr/lib/python3/dist-packages/gunicorn/util.py", line 366, in import_app
    __import__(module)
  File "/home/artem/poeapi/poeapi/__init__.py", line 4, in <module>
    from .celery import app as celery_app
  File "/home/artem/poeapi/poeapi/celery.py", line 3, in <module>
    from celery import Celery
ImportError: No module named 'celery'
[2020-01-27 17:44:20 +0000] [28964] [INFO] Worker exiting (pid: 28964)
[2020-01-27 17:44:20 +0000] [28961] [INFO] Shutting down: Master
[2020-01-27 17:44:20 +0000] [28961] [INFO] Reason: Worker failed to boot.
[2020-01-27 17:44:24 +0000] [28965] [INFO] Starting gunicorn 19.4.5
[2020-01-27 17:44:24 +0000] [28965] [INFO] Listening at: http://127.0.0.1:12345 (28965)
[2020-01-27 17:44:24 +0000] [28965] [INFO] Using worker: sync
[2020-01-27 17:44:24 +0000] [28968] [INFO] Booting worker with pid: 28968
[2020-01-27 17:44:24 +0000] [28968] [ERROR] Exception in worker process:
Traceback (most recent call last):
  File "/usr/lib/python3/dist-packages/gunicorn/arbiter.py", line 515, in spawn_worker
    worker.init_process()
  File "/usr/lib/python3/dist-packages/gunicorn/workers/base.py", line 122, in init_process
    self.load_wsgi()
  File "/usr/lib/python3/dist-packages/gunicorn/workers/base.py", line 130, in load_wsgi
    self.wsgi = self.app.wsgi()
  File "/usr/lib/python3/dist-packages/gunicorn/app/base.py", line 67, in wsgi
    self.callable = self.load()
  File "/usr/lib/python3/dist-packages/gunicorn/app/wsgiapp.py", line 65, in load
    return self.load_wsgiapp()
  File "/usr/lib/python3/dist-packages/gunicorn/app/wsgiapp.py", line 52, in load_wsgiapp
    return util.import_app(self.app_uri)
  File "/usr/lib/python3/dist-packages/gunicorn/util.py", line 366, in import_app
    __import__(module)
  File "/home/artem/poeapi/poeapi/__init__.py", line 4, in <module>
    from .celery import app as celery_app
  File "/home/artem/poeapi/poeapi/celery.py", line 3, in <module>
    from celery import Celery
ImportError: No module named 'celery'
Traceback (most recent call last):
  File "/usr/lib/python3/dist-packages/gunicorn/arbiter.py", line 515, in spawn_worker
    worker.init_process()
  File "/usr/lib/python3/dist-packages/gunicorn/workers/base.py", line 122, in init_process
    self.load_wsgi()
  File "/usr/lib/python3/dist-packages/gunicorn/workers/base.py", line 130, in load_wsgi
    self.wsgi = self.app.wsgi()
  File "/usr/lib/python3/dist-packages/gunicorn/app/base.py", line 67, in wsgi
    self.callable = self.load()
  File "/usr/lib/python3/dist-packages/gunicorn/app/wsgiapp.py", line 65, in load
    return self.load_wsgiapp()
  File "/usr/lib/python3/dist-packages/gunicorn/app/wsgiapp.py", line 52, in load_wsgiapp
    return util.import_app(self.app_uri)
  File "/usr/lib/python3/dist-packages/gunicorn/util.py", line 366, in import_app
    __import__(module)
  File "/home/artem/poeapi/poeapi/__init__.py", line 4, in <module>
    from .celery import app as celery_app
  File "/home/artem/poeapi/poeapi/celery.py", line 3, in <module>
    from celery import Celery
ImportError: No module named 'celery'
[2020-01-27 17:44:24 +0000] [28968] [INFO] Worker exiting (pid: 28968)
[2020-01-27 17:44:24 +0000] [28965] [INFO] Shutting down: Master
[2020-01-27 17:44:24 +0000] [28965] [INFO] Reason: Worker failed to boot.
[2020-01-29 15:05:23 +0000] [27597] [INFO] Starting gunicorn 19.4.5
[2020-01-29 15:05:23 +0000] [27597] [INFO] Listening at: http://127.0.0.1:12345 (27597)
[2020-01-29 15:05:23 +0000] [27597] [INFO] Using worker: sync
[2020-01-29 15:05:23 +0000] [27600] [INFO] Booting worker with pid: 27600
[2020-01-29 15:05:23 +0000] [27600] [ERROR] Exception in worker process:
Traceback (most recent call last):
  File "/usr/lib/python3/dist-packages/gunicorn/arbiter.py", line 515, in spawn_worker
    worker.init_process()
  File "/usr/lib/python3/dist-packages/gunicorn/workers/base.py", line 122, in init_process
    self.load_wsgi()
  File "/usr/lib/python3/dist-packages/gunicorn/workers/base.py", line 130, in load_wsgi
    self.wsgi = self.app.wsgi()
  File "/usr/lib/python3/dist-packages/gunicorn/app/base.py", line 67, in wsgi
    self.callable = self.load()
  File "/usr/lib/python3/dist-packages/gunicorn/app/wsgiapp.py", line 65, in load
    return self.load_wsgiapp()
  File "/usr/lib/python3/dist-packages/gunicorn/app/wsgiapp.py", line 52, in load_wsgiapp
    return util.import_app(self.app_uri)
  File "/usr/lib/python3/dist-packages/gunicorn/util.py", line 366, in import_app
    __import__(module)
  File "/home/artem/poeapi/poeapi/__init__.py", line 4, in <module>
    from .celery import app as celery_app
  File "/home/artem/poeapi/poeapi/celery.py", line 3, in <module>
    from celery import Celery
ModuleNotFoundError: No module named 'celery'
Traceback (most recent call last):
  File "/usr/lib/python3/dist-packages/gunicorn/arbiter.py", line 515, in spawn_worker
    worker.init_process()
  File "/usr/lib/python3/dist-packages/gunicorn/workers/base.py", line 122, in init_process
    self.load_wsgi()
  File "/usr/lib/python3/dist-packages/gunicorn/workers/base.py", line 130, in load_wsgi
    self.wsgi = self.app.wsgi()
  File "/usr/lib/python3/dist-packages/gunicorn/app/base.py", line 67, in wsgi
    self.callable = self.load()
  File "/usr/lib/python3/dist-packages/gunicorn/app/wsgiapp.py", line 65, in load
    return self.load_wsgiapp()
  File "/usr/lib/python3/dist-packages/gunicorn/app/wsgiapp.py", line 52, in load_wsgiapp
    return util.import_app(self.app_uri)
  File "/usr/lib/python3/dist-packages/gunicorn/util.py", line 366, in import_app
    __import__(module)
  File "/home/artem/poeapi/poeapi/__init__.py", line 4, in <module>
    from .celery import app as celery_app
  File "/home/artem/poeapi/poeapi/celery.py", line 3, in <module>
    from celery import Celery
ModuleNotFoundError: No module named 'celery'
[2020-01-29 15:05:23 +0000] [27600] [INFO] Worker exiting (pid: 27600)
[2020-01-29 15:05:23 +0000] [27597] [INFO] Shutting down: Master
[2020-01-29 15:05:23 +0000] [27597] [INFO] Reason: Worker failed to boot.
[2020-01-29 15:18:14 +0000] [28439] [INFO] Starting gunicorn 19.4.5
[2020-01-29 15:18:14 +0000] [28439] [INFO] Listening at: http://127.0.0.1:12345 (28439)
[2020-01-29 15:18:14 +0000] [28439] [INFO] Using worker: sync
[2020-01-29 15:18:14 +0000] [28442] [INFO] Booting worker with pid: 28442
[2020-01-29 15:18:14 +0000] [28442] [ERROR] Exception in worker process:
Traceback (most recent call last):
  File "/usr/lib/python3/dist-packages/gunicorn/arbiter.py", line 515, in spawn_worker
    worker.init_process()
  File "/usr/lib/python3/dist-packages/gunicorn/workers/base.py", line 122, in init_process
    self.load_wsgi()
  File "/usr/lib/python3/dist-packages/gunicorn/workers/base.py", line 130, in load_wsgi
    self.wsgi = self.app.wsgi()
  File "/usr/lib/python3/dist-packages/gunicorn/app/base.py", line 67, in wsgi
    self.callable = self.load()
  File "/usr/lib/python3/dist-packages/gunicorn/app/wsgiapp.py", line 65, in load
    return self.load_wsgiapp()
  File "/usr/lib/python3/dist-packages/gunicorn/app/wsgiapp.py", line 52, in load_wsgiapp
    return util.import_app(self.app_uri)
  File "/usr/lib/python3/dist-packages/gunicorn/util.py", line 366, in import_app
    __import__(module)
  File "/home/artem/poeapi/poeapi/__init__.py", line 4, in <module>
    from .celery import app as celery_app
  File "/home/artem/poeapi/poeapi/celery.py", line 3, in <module>
    from celery import Celery
ModuleNotFoundError: No module named 'celery'
Traceback (most recent call last):
  File "/usr/lib/python3/dist-packages/gunicorn/arbiter.py", line 515, in spawn_worker
    worker.init_process()
  File "/usr/lib/python3/dist-packages/gunicorn/workers/base.py", line 122, in init_process
    self.load_wsgi()
  File "/usr/lib/python3/dist-packages/gunicorn/workers/base.py", line 130, in load_wsgi
    self.wsgi = self.app.wsgi()
  File "/usr/lib/python3/dist-packages/gunicorn/app/base.py", line 67, in wsgi
    self.callable = self.load()
  File "/usr/lib/python3/dist-packages/gunicorn/app/wsgiapp.py", line 65, in load
    return self.load_wsgiapp()
  File "/usr/lib/python3/dist-packages/gunicorn/app/wsgiapp.py", line 52, in load_wsgiapp
    return util.import_app(self.app_uri)
  File "/usr/lib/python3/dist-packages/gunicorn/util.py", line 366, in import_app
    __import__(module)
  File "/home/artem/poeapi/poeapi/__init__.py", line 4, in <module>
    from .celery import app as celery_app
  File "/home/artem/poeapi/poeapi/celery.py", line 3, in <module>
    from celery import Celery
ModuleNotFoundError: No module named 'celery'
[2020-01-29 15:18:14 +0000] [28442] [INFO] Worker exiting (pid: 28442)
[2020-01-29 15:18:14 +0000] [28439] [INFO] Shutting down: Master
[2020-01-29 15:18:14 +0000] [28439] [INFO] Reason: Worker failed to boot.
[2020-01-29 15:18:15 +0000] [28443] [INFO] Starting gunicorn 19.4.5
[2020-01-29 15:18:15 +0000] [28443] [INFO] Listening at: http://127.0.0.1:12345 (28443)
[2020-01-29 15:18:15 +0000] [28443] [INFO] Using worker: sync
[2020-01-29 15:18:16 +0000] [28446] [INFO] Booting worker with pid: 28446
[2020-01-29 15:18:16 +0000] [28446] [ERROR] Exception in worker process:
Traceback (most recent call last):
  File "/usr/lib/python3/dist-packages/gunicorn/arbiter.py", line 515, in spawn_worker
    worker.init_process()
  File "/usr/lib/python3/dist-packages/gunicorn/workers/base.py", line 122, in init_process
    self.load_wsgi()
  File "/usr/lib/python3/dist-packages/gunicorn/workers/base.py", line 130, in load_wsgi
    self.wsgi = self.app.wsgi()
  File "/usr/lib/python3/dist-packages/gunicorn/app/base.py", line 67, in wsgi
    self.callable = self.load()
  File "/usr/lib/python3/dist-packages/gunicorn/app/wsgiapp.py", line 65, in load
    return self.load_wsgiapp()
  File "/usr/lib/python3/dist-packages/gunicorn/app/wsgiapp.py", line 52, in load_wsgiapp
    return util.import_app(self.app_uri)
  File "/usr/lib/python3/dist-packages/gunicorn/util.py", line 366, in import_app
    __import__(module)
  File "/home/artem/poeapi/poeapi/__init__.py", line 4, in <module>
    from .celery import app as celery_app
  File "/home/artem/poeapi/poeapi/celery.py", line 3, in <module>
    from celery import Celery
ModuleNotFoundError: No module named 'celery'
Traceback (most recent call last):
  File "/usr/lib/python3/dist-packages/gunicorn/arbiter.py", line 515, in spawn_worker
    worker.init_process()
  File "/usr/lib/python3/dist-packages/gunicorn/workers/base.py", line 122, in init_process
    self.load_wsgi()
  File "/usr/lib/python3/dist-packages/gunicorn/workers/base.py", line 130, in load_wsgi
    self.wsgi = self.app.wsgi()
  File "/usr/lib/python3/dist-packages/gunicorn/app/base.py", line 67, in wsgi
    self.callable = self.load()
  File "/usr/lib/python3/dist-packages/gunicorn/app/wsgiapp.py", line 65, in load
    return self.load_wsgiapp()
  File "/usr/lib/python3/dist-packages/gunicorn/app/wsgiapp.py", line 52, in load_wsgiapp
    return util.import_app(self.app_uri)
  File "/usr/lib/python3/dist-packages/gunicorn/util.py", line 366, in import_app
    __import__(module)
  File "/home/artem/poeapi/poeapi/__init__.py", line 4, in <module>
    from .celery import app as celery_app
  File "/home/artem/poeapi/poeapi/celery.py", line 3, in <module>
    from celery import Celery
ModuleNotFoundError: No module named 'celery'
[2020-01-29 15:18:16 +0000] [28446] [INFO] Worker exiting (pid: 28446)
[2020-01-29 15:18:16 +0000] [28443] [INFO] Shutting down: Master
[2020-01-29 15:18:16 +0000] [28443] [INFO] Reason: Worker failed to boot.
[2020-01-29 15:18:17 +0000] [28452] [INFO] Starting gunicorn 19.4.5
[2020-01-29 15:18:17 +0000] [28452] [INFO] Listening at: http://127.0.0.1:12345 (28452)
[2020-01-29 15:18:17 +0000] [28452] [INFO] Using worker: sync
[2020-01-29 15:18:17 +0000] [28455] [INFO] Booting worker with pid: 28455
[2020-01-29 15:18:17 +0000] [28455] [ERROR] Exception in worker process:
Traceback (most recent call last):
  File "/usr/lib/python3/dist-packages/gunicorn/arbiter.py", line 515, in spawn_worker
    worker.init_process()
  File "/usr/lib/python3/dist-packages/gunicorn/workers/base.py", line 122, in init_process
    self.load_wsgi()
  File "/usr/lib/python3/dist-packages/gunicorn/workers/base.py", line 130, in load_wsgi
    self.wsgi = self.app.wsgi()
  File "/usr/lib/python3/dist-packages/gunicorn/app/base.py", line 67, in wsgi
    self.callable = self.load()
  File "/usr/lib/python3/dist-packages/gunicorn/app/wsgiapp.py", line 65, in load
    return self.load_wsgiapp()
  File "/usr/lib/python3/dist-packages/gunicorn/app/wsgiapp.py", line 52, in load_wsgiapp
    return util.import_app(self.app_uri)
  File "/usr/lib/python3/dist-packages/gunicorn/util.py", line 366, in import_app
    __import__(module)
  File "/home/artem/poeapi/poeapi/__init__.py", line 4, in <module>
    from .celery import app as celery_app
  File "/home/artem/poeapi/poeapi/celery.py", line 3, in <module>
    from celery import Celery
ModuleNotFoundError: No module named 'celery'
Traceback (most recent call last):
  File "/usr/lib/python3/dist-packages/gunicorn/arbiter.py", line 515, in spawn_worker
    worker.init_process()
  File "/usr/lib/python3/dist-packages/gunicorn/workers/base.py", line 122, in init_process
    self.load_wsgi()
  File "/usr/lib/python3/dist-packages/gunicorn/workers/base.py", line 130, in load_wsgi
    self.wsgi = self.app.wsgi()
  File "/usr/lib/python3/dist-packages/gunicorn/app/base.py", line 67, in wsgi
    self.callable = self.load()
  File "/usr/lib/python3/dist-packages/gunicorn/app/wsgiapp.py", line 65, in load
    return self.load_wsgiapp()
  File "/usr/lib/python3/dist-packages/gunicorn/app/wsgiapp.py", line 52, in load_wsgiapp
    return util.import_app(self.app_uri)
  File "/usr/lib/python3/dist-packages/gunicorn/util.py", line 366, in import_app
    __import__(module)
  File "/home/artem/poeapi/poeapi/__init__.py", line 4, in <module>
    from .celery import app as celery_app
  File "/home/artem/poeapi/poeapi/celery.py", line 3, in <module>
    from celery import Celery
ModuleNotFoundError: No module named 'celery'
[2020-01-29 15:18:17 +0000] [28455] [INFO] Worker exiting (pid: 28455)
[2020-01-29 15:18:17 +0000] [28452] [INFO] Shutting down: Master
[2020-01-29 15:18:17 +0000] [28452] [INFO] Reason: Worker failed to boot.
[2020-01-29 15:18:19 +0000] [28456] [INFO] Starting gunicorn 19.4.5
[2020-01-29 15:18:19 +0000] [28456] [INFO] Listening at: http://127.0.0.1:12345 (28456)
[2020-01-29 15:18:19 +0000] [28456] [INFO] Using worker: sync
[2020-01-29 15:18:19 +0000] [28459] [INFO] Booting worker with pid: 28459
[2020-01-29 15:18:19 +0000] [28459] [ERROR] Exception in worker process:
Traceback (most recent call last):
  File "/usr/lib/python3/dist-packages/gunicorn/arbiter.py", line 515, in spawn_worker
    worker.init_process()
  File "/usr/lib/python3/dist-packages/gunicorn/workers/base.py", line 122, in init_process
    self.load_wsgi()
  File "/usr/lib/python3/dist-packages/gunicorn/workers/base.py", line 130, in load_wsgi
    self.wsgi = self.app.wsgi()
  File "/usr/lib/python3/dist-packages/gunicorn/app/base.py", line 67, in wsgi
    self.callable = self.load()
  File "/usr/lib/python3/dist-packages/gunicorn/app/wsgiapp.py", line 65, in load
    return self.load_wsgiapp()
  File "/usr/lib/python3/dist-packages/gunicorn/app/wsgiapp.py", line 52, in load_wsgiapp
    return util.import_app(self.app_uri)
  File "/usr/lib/python3/dist-packages/gunicorn/util.py", line 366, in import_app
    __import__(module)
  File "/home/artem/poeapi/poeapi/__init__.py", line 4, in <module>
    from .celery import app as celery_app
  File "/home/artem/poeapi/poeapi/celery.py", line 3, in <module>
    from celery import Celery
ModuleNotFoundError: No module named 'celery'
Traceback (most recent call last):
  File "/usr/lib/python3/dist-packages/gunicorn/arbiter.py", line 515, in spawn_worker
    worker.init_process()
  File "/usr/lib/python3/dist-packages/gunicorn/workers/base.py", line 122, in init_process
    self.load_wsgi()
  File "/usr/lib/python3/dist-packages/gunicorn/workers/base.py", line 130, in load_wsgi
    self.wsgi = self.app.wsgi()
  File "/usr/lib/python3/dist-packages/gunicorn/app/base.py", line 67, in wsgi
    self.callable = self.load()
  File "/usr/lib/python3/dist-packages/gunicorn/app/wsgiapp.py", line 65, in load
    return self.load_wsgiapp()
  File "/usr/lib/python3/dist-packages/gunicorn/app/wsgiapp.py", line 52, in load_wsgiapp
    return util.import_app(self.app_uri)
  File "/usr/lib/python3/dist-packages/gunicorn/util.py", line 366, in import_app
    __import__(module)
  File "/home/artem/poeapi/poeapi/__init__.py", line 4, in <module>
    from .celery import app as celery_app
  File "/home/artem/poeapi/poeapi/celery.py", line 3, in <module>
    from celery import Celery
ModuleNotFoundError: No module named 'celery'
[2020-01-29 15:18:19 +0000] [28459] [INFO] Worker exiting (pid: 28459)
[2020-01-29 15:18:19 +0000] [28456] [INFO] Shutting down: Master
[2020-01-29 15:18:19 +0000] [28456] [INFO] Reason: Worker failed to boot.
[2020-01-29 15:18:22 +0000] [28464] [INFO] Starting gunicorn 19.4.5
[2020-01-29 15:18:22 +0000] [28464] [INFO] Listening at: http://127.0.0.1:12345 (28464)
[2020-01-29 15:18:22 +0000] [28464] [INFO] Using worker: sync
[2020-01-29 15:18:22 +0000] [28467] [INFO] Booting worker with pid: 28467
[2020-01-29 15:18:22 +0000] [28467] [ERROR] Exception in worker process:
Traceback (most recent call last):
  File "/usr/lib/python3/dist-packages/gunicorn/arbiter.py", line 515, in spawn_worker
    worker.init_process()
  File "/usr/lib/python3/dist-packages/gunicorn/workers/base.py", line 122, in init_process
    self.load_wsgi()
  File "/usr/lib/python3/dist-packages/gunicorn/workers/base.py", line 130, in load_wsgi
    self.wsgi = self.app.wsgi()
  File "/usr/lib/python3/dist-packages/gunicorn/app/base.py", line 67, in wsgi
    self.callable = self.load()
  File "/usr/lib/python3/dist-packages/gunicorn/app/wsgiapp.py", line 65, in load
    return self.load_wsgiapp()
  File "/usr/lib/python3/dist-packages/gunicorn/app/wsgiapp.py", line 52, in load_wsgiapp
    return util.import_app(self.app_uri)
  File "/usr/lib/python3/dist-packages/gunicorn/util.py", line 366, in import_app
    __import__(module)
  File "/home/artem/poeapi/poeapi/__init__.py", line 4, in <module>
    from .celery import app as celery_app
  File "/home/artem/poeapi/poeapi/celery.py", line 3, in <module>
    from celery import Celery
ModuleNotFoundError: No module named 'celery'
Traceback (most recent call last):
  File "/usr/lib/python3/dist-packages/gunicorn/arbiter.py", line 515, in spawn_worker
    worker.init_process()
  File "/usr/lib/python3/dist-packages/gunicorn/workers/base.py", line 122, in init_process
    self.load_wsgi()
  File "/usr/lib/python3/dist-packages/gunicorn/workers/base.py", line 130, in load_wsgi
    self.wsgi = self.app.wsgi()
  File "/usr/lib/python3/dist-packages/gunicorn/app/base.py", line 67, in wsgi
    self.callable = self.load()
  File "/usr/lib/python3/dist-packages/gunicorn/app/wsgiapp.py", line 65, in load
    return self.load_wsgiapp()
  File "/usr/lib/python3/dist-packages/gunicorn/app/wsgiapp.py", line 52, in load_wsgiapp
    return util.import_app(self.app_uri)
  File "/usr/lib/python3/dist-packages/gunicorn/util.py", line 366, in import_app
    __import__(module)
  File "/home/artem/poeapi/poeapi/__init__.py", line 4, in <module>
    from .celery import app as celery_app
  File "/home/artem/poeapi/poeapi/celery.py", line 3, in <module>
    from celery import Celery
ModuleNotFoundError: No module named 'celery'
[2020-01-29 15:18:22 +0000] [28467] [INFO] Worker exiting (pid: 28467)
[2020-01-29 15:18:22 +0000] [28464] [INFO] Shutting down: Master
[2020-01-29 15:18:22 +0000] [28464] [INFO] Reason: Worker failed to boot.
[2020-01-29 15:22:47 +0000] [28803] [INFO] Starting gunicorn 19.4.5
[2020-01-29 15:22:47 +0000] [28803] [INFO] Listening at: http://127.0.0.1:12345 (28803)
[2020-01-29 15:22:47 +0000] [28803] [INFO] Using worker: sync
[2020-01-29 15:22:47 +0000] [28806] [INFO] Booting worker with pid: 28806
[2020-01-29 15:22:47 +0000] [28806] [ERROR] Exception in worker process:
Traceback (most recent call last):
  File "/usr/lib/python3/dist-packages/gunicorn/arbiter.py", line 515, in spawn_worker
    worker.init_process()
  File "/usr/lib/python3/dist-packages/gunicorn/workers/base.py", line 122, in init_process
    self.load_wsgi()
  File "/usr/lib/python3/dist-packages/gunicorn/workers/base.py", line 130, in load_wsgi
    self.wsgi = self.app.wsgi()
  File "/usr/lib/python3/dist-packages/gunicorn/app/base.py", line 67, in wsgi
    self.callable = self.load()
  File "/usr/lib/python3/dist-packages/gunicorn/app/wsgiapp.py", line 65, in load
    return self.load_wsgiapp()
  File "/usr/lib/python3/dist-packages/gunicorn/app/wsgiapp.py", line 52, in load_wsgiapp
    return util.import_app(self.app_uri)
  File "/usr/lib/python3/dist-packages/gunicorn/util.py", line 366, in import_app
    __import__(module)
ModuleNotFoundError: No module named 'poeapi.wsgi'
Traceback (most recent call last):
  File "/usr/lib/python3/dist-packages/gunicorn/arbiter.py", line 515, in spawn_worker
    worker.init_process()
  File "/usr/lib/python3/dist-packages/gunicorn/workers/base.py", line 122, in init_process
    self.load_wsgi()
  File "/usr/lib/python3/dist-packages/gunicorn/workers/base.py", line 130, in load_wsgi
    self.wsgi = self.app.wsgi()
  File "/usr/lib/python3/dist-packages/gunicorn/app/base.py", line 67, in wsgi
    self.callable = self.load()
  File "/usr/lib/python3/dist-packages/gunicorn/app/wsgiapp.py", line 65, in load
    return self.load_wsgiapp()
  File "/usr/lib/python3/dist-packages/gunicorn/app/wsgiapp.py", line 52, in load_wsgiapp
    return util.import_app(self.app_uri)
  File "/usr/lib/python3/dist-packages/gunicorn/util.py", line 366, in import_app
    __import__(module)
ModuleNotFoundError: No module named 'poeapi.wsgi'
[2020-01-29 15:22:47 +0000] [28806] [INFO] Worker exiting (pid: 28806)
[2020-01-29 15:22:47 +0000] [28803] [INFO] Shutting down: Master
[2020-01-29 15:22:47 +0000] [28803] [INFO] Reason: Worker failed to boot.
[2020-01-29 15:23:07 +0000] [28855] [INFO] Starting gunicorn 19.4.5
[2020-01-29 15:23:07 +0000] [28855] [INFO] Listening at: http://127.0.0.1:12345 (28855)
[2020-01-29 15:23:07 +0000] [28855] [INFO] Using worker: sync
[2020-01-29 15:23:07 +0000] [28858] [INFO] Booting worker with pid: 28858
[2020-01-29 15:23:07 +0000] [28858] [ERROR] Exception in worker process:
Traceback (most recent call last):
  File "/usr/lib/python3/dist-packages/gunicorn/arbiter.py", line 515, in spawn_worker
    worker.init_process()
  File "/usr/lib/python3/dist-packages/gunicorn/workers/base.py", line 122, in init_process
    self.load_wsgi()
  File "/usr/lib/python3/dist-packages/gunicorn/workers/base.py", line 130, in load_wsgi
    self.wsgi = self.app.wsgi()
  File "/usr/lib/python3/dist-packages/gunicorn/app/base.py", line 67, in wsgi
    self.callable = self.load()
  File "/usr/lib/python3/dist-packages/gunicorn/app/wsgiapp.py", line 65, in load
    return self.load_wsgiapp()
  File "/usr/lib/python3/dist-packages/gunicorn/app/wsgiapp.py", line 52, in load_wsgiapp
    return util.import_app(self.app_uri)
  File "/usr/lib/python3/dist-packages/gunicorn/util.py", line 366, in import_app
    __import__(module)
ModuleNotFoundError: No module named 'poeapi.wsgi'
Traceback (most recent call last):
  File "/usr/lib/python3/dist-packages/gunicorn/arbiter.py", line 515, in spawn_worker
    worker.init_process()
  File "/usr/lib/python3/dist-packages/gunicorn/workers/base.py", line 122, in init_process
    self.load_wsgi()
  File "/usr/lib/python3/dist-packages/gunicorn/workers/base.py", line 130, in load_wsgi
    self.wsgi = self.app.wsgi()
  File "/usr/lib/python3/dist-packages/gunicorn/app/base.py", line 67, in wsgi
    self.callable = self.load()
  File "/usr/lib/python3/dist-packages/gunicorn/app/wsgiapp.py", line 65, in load
    return self.load_wsgiapp()
  File "/usr/lib/python3/dist-packages/gunicorn/app/wsgiapp.py", line 52, in load_wsgiapp
    return util.import_app(self.app_uri)
  File "/usr/lib/python3/dist-packages/gunicorn/util.py", line 366, in import_app
    __import__(module)
ModuleNotFoundError: No module named 'poeapi.wsgi'
[2020-01-29 15:23:07 +0000] [28858] [INFO] Worker exiting (pid: 28858)
[2020-01-29 15:23:07 +0000] [28855] [INFO] Shutting down: Master
[2020-01-29 15:23:07 +0000] [28855] [INFO] Reason: Worker failed to boot.
